Workbook

Sheet Start_Here
A1: Start here — what this workbook is, what changed, and what still needs your data
A2: CP-45 (row 46 of 'MBA_GEN_60_Bloomberg_Capstone_Projects'). Built from your 15-Oct-2026 Bloomberg screenshots, your draft plan, and the project brief.
A4: Colour legend
A5: Blue text | B5: Value typed from a Bloomberg screenshot, or an assumption you can change
A6: Black text | B6: Formula
A7: Green text | B7: Link to another sheet
A8: Yellow fill | B8: Key assumption or headline output
A10: Sheet map
A11: Summary | B11: Headline results and findings (live)
A12: Assumptions | B12: All judgement inputs + scenario switch (Base / Adverse / Severe)
A13: ROI_ULVR / ROI_NESN / ROI_WIL | B13: Year-by-year cost-benefit: status quo vs central database vs permissioned blockchain
A14: MC_Results | B14: Monte Carlo (20,000 draws × 4 regimes) — static from Python
A15: Sensitivity | B15: Tornado + coverage × substitution heat map — static from Python
A16: Risk_Index | B16: Composite risk index built on real indicators, three weight sets
A17: Supply_Chain | B17: SPLC panels, Wilmar supplier table, brand-owner supplier tables, HHI, coverage
A18: News_Events | B18: Hand-coded controversy log (12M window)
A19: ESG | B19: BESG scores and GHG scopes
A20: Fundamentals | B20: Income statement, balance sheet and cash-flow extracts + ratios
A21: Market_Data | B21: Snapshot and CPO futures stats
A22: Price_Analytics | B22: Aligned daily prices, returns, volatility, correlation, beta
A23: Next_Steps | B23: Data still to pull and how
A25: Review of the draft plan — what I changed and why
A26: Issue in the draft | B26: Why it matters | C26: Fix applied here | D26: Still for you to do
A27: The Python code is cut off mid-formula ('+ 0.20 *') and the simulation / ROI code it promises is not in the file. | B27: Nothing runs; RQ3/RQ4 have no engine. | C27: Rebuilt end-to-end: palm_oil_traceability_model.py (market stats, NPV model, Monte Carlo, tornado, grid) and this workbook; Excel and Python NPVs tie exactly. | D27: Run the script after changing any assumption; paste refreshed tables into MC_Results/Sensitivity.
A28: 50 synthetic suppliers with random ESG, news hits and RSPO flags. | B28: Random inputs cannot answer RQ1–RQ3; an examiner will ask for the Bloomberg evidence. | C28: Replaced with the real Bloomberg data you captured (fundamentals, ESG, SPLC suppliers, news, prices). | D28: Pull the full SPLC lists and 5Y history (Next_Steps).
A29: The risk index weights (0.35 / 0.25 / 0.20 …) are chosen by hand and then a model is 'validated' against it. | B29: Circular: the model can only rediscover the weights you typed. | C29: Weights are explicit, editable, tested under three weight sets; ranking-stability check added. | D29: Calibrate against an outcome (forward drawdown, controversy count after events) once you have more firms and 5Y data.
A30: The chain 'mill → Wilmar → Unilever/Nestlé' is presented as given. | B30: SPLC does not show it; your own news screen shows Nestlé's palm partners as Musim Mas and AAK. | C30: Flagged with evidence on Supply_Chain; opacity used as a finding. | D30: Search SPLC for Wilmar / IOI / Musim Mas / AAK / Cargill; add each brand owner's published mill list.
A31: Only 'with vs without blockchain' is compared. | B31: Most of the benefit comes from traceability itself; the blockchain's value is the increment over a central database. | C31: Three options modelled; incremental NPV and P(blockchain beats database) reported. | D31: Defend the effectiveness gap (Assumptions!C43 vs D43) with evidence — it decides the answer.
A32: Price series called 'KOA Comdty'. | B32: Your screens use KOZ6 Comdty (single Dec-26 contract, MYR). | C32: Documented on Market_Data; all stats use KOZ6. | D32: Use a continuous series (KO1 Comdty — confirm) and state the roll rule.
A33: No regulatory timeline in the model. | B33: EU Deforestation Regulation obligations for large/medium operators apply from 30-Dec-2026 (per the European Commission's trade site, as fetched 22-Oct-2026). | C33: Regulatory loss channel with fine rate, EU share, scenarios (Adverse/Severe = stricter enforcement). | D33: Confirm palm oil's scope, the penalty ceiling and any further delay in the final regulation text before quoting.
A34: Zero-knowledge proofs + Hyperledger Fabric/Corda in the architecture box. | B34: ZKPs add cost and complexity; the brief needs the economics, not a build. | C34: Not modelled; architecture cost is one capex/opex line. | D34: Keep ZKPs as an optional extension (selective disclosure of supplier prices); compare Fabric / Corda / permissioned EVM qualitatively.
A35: ESG score used as a predictor. | B35: Wilmar's BESG score rose while its emissions rose — scores follow disclosure. | C35: Scored alongside conduct-risk, distress, news and balance-sheet indicators. | D35: Add disclosure-quality and certification-coverage variables.
A36: Data comparability. | B36: Unilever FY24–25 restated for the ice-cream demerger; Unilever Scope 3 has series breaks; different news filters per firm; EUR/CHF/USD. | C36: Caveats on each sheet; FX is an explicit assumption; ratios not levels. | D36: Re-run all three firms with identical filters; replace illustrative FX with Bloomberg FX.

Sheet Summary
A1: CP-45 Blockchain Sustainable Palm Oil Traceability — Unilever · Nestlé · Wilmar
A2: Headline results (live links; scenario = Assumptions!B13). Model inputs marked ASSUMPTION are placeholders: read the numbers as decision logic, not forecasts.
A4: Active scenario | B4: =Assumptions!B13 -> Base
A6: Headline metric | B6: Unilever | C6: Nestlé | D6: Wilmar | E6: Where it comes from
A7: Cost-benefit (USD m, PV over 7 years vs status quo)
A8: NPV benefit — central database | B8: =ROI_ULVR!E71 -> 20.177473 | C8: =ROI_NESN!E71 -> 44.412856 | D8: =ROI_WIL!E71 -> 89.968344 | E8: ROI_ sheets
A9: NPV benefit — permissioned blockchain | B9: =ROI_ULVR!E72 -> 15.992594 | C9: =ROI_NESN!E72 -> 46.67889 | D9: =ROI_WIL!E72 -> 86.363854 | E9: ROI_ sheets
A10: Blockchain minus database (NPV) | B10: =ROI_ULVR!E81 -> -4.1848793 | C10: =ROI_NESN!E81 -> 2.2660343 | D10: =ROI_WIL!E81 -> -3.6044897 | E10: Negative = a plain database is the better buy at these inputs
A11: Benefit / programme cost — database | B11: =ROI_ULVR!G71 -> 1.8130373 | C11: =ROI_NESN!G71 -> 3.1134386 | D11: =ROI_WIL!G71 -> 2.1099255
A12: Benefit / programme cost — blockchain | B12: =ROI_ULVR!G72 -> 1.4077029 | C12: =ROI_NESN!G72 -> 2.3560299 | D12: =ROI_WIL!G72 -> 1.7289245
A13: Discounted payback (yrs) — database | B13: =ROI_ULVR!I71 -> 3 | C13: =ROI_NESN!I71 -> 2 | D13: =ROI_WIL!I71 -> 3
A14: Discounted payback (yrs) — blockchain | B14: =ROI_ULVR!I72 -> 5 | C14: =ROI_NESN!I72 -> 3 | D14: =ROI_WIL!I72 -> 4
A15: Break-even regulatory-risk multiplier — blockchain | B15: =ROI_ULVR!H72 -> 0.34310807 | C15: =ROI_NESN!H72 -> 0.0089094669 | D15: =ROI_WIL!H72 -> 0 | E15: Factor on p_reg at which NPV = 0 (0 = pays even with no regulatory risk)
A17: Monte Carlo, mixed enforcement regimes (static, from Python)
A18: P(NPV > 0) — database | B18: =MC_Results!H11 -> 0.78925 | C18: =MC_Results!H19 -> 0.9332 | D18: =MC_Results!H27 -> 0.88505
A19: P(NPV > 0) — blockchain | B19: =MC_Results!H12 -> 0.6236 | C19: =MC_Results!H20 -> 0.8275 | D19: =MC_Results!H28 -> 0.7567
A20: P(blockchain beats database) | B20: =MC_Results!I12 -> 0.35255 | C20: =MC_Results!I20 -> 0.42045 | D20: =MC_Results!I28 -> 0.38345
A22: Risk & visibility evidence (live)
A23: Composite traceability risk index (0–100, base weights) | B23: =Risk_Index!H18 -> 53.004404 | C23: =Risk_Index!I18 -> 39.940302 | D23: =Risk_Index!J18 -> 63.512421 | E23: Risk_Index (relative ranking of 3 firms only)
A24: Palm/plantation nodes visible in SPLC top suppliers | B24: =Supply_Chain!B148 -> 0 | C24: =Supply_Chain!B117 -> 0 | D24: =Supply_Chain!B84 -> 10 | E24: Visible = shown on the captured screens (Wilmar: of 24 visible suppliers)
A25: Visible supplier cost as % of COGS (lower bound) | B25: =Supply_Chain!B147 -> 0.1657 | C25: =Supply_Chain!B116 -> 0.1287 | D25: =Supply_Chain!B82 -> 0.0266
A26: Adverse news severity, last 12M (hand-coded) | B26: =News_Events!C7 -> 12 | C26: =News_Events!C8 -> 1 | D26: =News_Events!C9 -> 19 | E26: Different screen filters per firm — see News_Events warning
A28: What the evidence says (default inputs, base scenario)
A29: 1. Traceability pays in most simulated worlds (central database positive in 79–93% of mixed-regime draws); the technology choice is the close call. A central database + satellite/audit stack captures most of the benefit. At base inputs the blockchain only matches the database if its assurance value reaches ~0.88 (Nestlé), ~0.92 (Wilmar) or ~0.96 (Unilever) versus 0.80 for the database; under Adverse enforcement the parity points fall to ~0.82–0.87. In the mixed Monte Carlo the blockchain wins in roughly 35–42% of worlds. That is the honest answer to RQ4 — and a stronger capstone than 'blockchain always helps'.
A30: 2. Bloomberg SPLC cannot see the palm chain. None of Unilever's or Nestlé's top-24 suppliers is a palm trader or plantation, Wilmar is not in either list, and the plantation nodes visible for Wilmar are ~0.4% of its cost base. The draft's 'mill → Wilmar → Unilever/Nestlé' chain is an assumption, not an SPLC finding (your Nestlé news screen shows Musim Mas and AAK as Nestlé's palm partners). This opacity IS the problem the blockchain would solve — use it as your motivating evidence, and add company mill lists as a second source.
A31: 3. Wilmar ranks highest-risk on the composite index, driven by interest cover (~2.1x vs 8–9x), supplier conduct-risk flags (37% of listed suppliers) and the news record: the May-2026 Indonesian export under-invoicing probe, a corruption conviction of a unit executive, and the Russian asset-seizure report. Note these are governance/legal events, not deforestation events — the 'traceability' narrative must be separated from the 'governance' one.
A32: 4. Wilmar's BESG score more than doubled (2.71 → 6.15) while reported Scope 1 emissions rose 2.6x: scores track disclosure, not footprint. Do not use a BESG score alone as a traceability-risk predictor (RQ1).
A33: 5. KOZ6 palm oil sits ~9% below its 8-Sep-26 high (MYR 5,115 → 4,666) after a +18% rise over the range. With only ~8 weeks of aligned prices, correlations with the three equities are statistically zero (|ρ| < 0.35 band) — pull ≥5 years of data before claiming any price–equity link (RQ2).

Sheet Assumptions
A1: Assumptions — every judgement input for the ROI / NPV model lives here
A2: Blue = input you can change (yellow = most influential). Green = pulled from Fundamentals. These are PLANNING-GRADE PLACEHOLDERS, not Bloomberg facts: calibrate each one and cite the source in the Basis column.
A4: A. Global inputs
A5: Discount rate | B5: 0.08 | F5: Use each firm's WACC (Bloomberg WACC <GO>); 8% is a generic consumer-staples/agri placeholder.
A6: Nominal growth of revenue, COGS and opex | B6: 0.02 | F6: Placeholder; replace with consensus growth (see Fundamentals 2026E/27E).
A7: Realised fine, % of EU turnover when non-compliant | B7: 0.02 | F7: EUDR maximum is at least 4% of EU turnover; base case assumes half of that is realised. Verify against the final regulation text.
A8: Price premium on re-sourced compliant volume | B8: 0.06 | F8: Placeholder; calibrate to RSPO / segregated-supply premiums.
A9: Share of non-traceable EU-bound volume excluded / re-sourced | B9: 0.3 | F9: Placeholder; supplier-exclusion rate under a compliance-only sourcing policy.
A10: Baseline traceable share today (c0) | B10: 0.3 | F10: Placeholder; use each firm's published certified / traceable-to-mill percentage.
A11: FX: EUR→USD | B11: 1.15 | F11: ILLUSTRATIVE — replace with Bloomberg FX on the data date (EURUSD Curncy).
A12: FX: CHF→USD | B12: 1.25 | F12: ILLUSTRATIVE — replace with Bloomberg FX on the data date (USDCHF Curncy, inverted).
A13: Active scenario (pick: Base / Adverse / Severe) | B13: Base | F13: Drives the three ROI sheets and the live numbers on Summary. Monte Carlo tables are static (run in Python).
A15: Scenario multipliers | B15: Regulatory prob. × | C15: Controversy prob. × | D15: Substitution premium × | E15: CPO price level ×
A16: Base | B16: 1 | C16: 1 | D16: 1 | E16: 1 | F16: Severe = strict EUDR enforcement + palm price level +30% (supply squeeze).
A17: Adverse | B17: 2 | C17: 1.5 | D17: 1.5 | E17: 1
A18: Severe | B18: 4 | C18: 2.5 | D18: 2.5 | E18: 1.3
A19: Active multipliers | B19: =INDEX(B16:B18,MATCH($B$13,$A$16:$A$18,0)) -> 1 | C19: =INDEX(C16:C18,MATCH($B$13,$A$16:$A$18,0)) -> 1 | D19: =INDEX(D16:D18,MATCH($B$13,$A$16:$A$18,0)) -> 1 | E19: =INDEX(E16:E18,MATCH($B$13,$A$16:$A$18,0)) -> 1
A21: B. Firm profiles (USD m unless stated)
A22: Parameter | B22: Unilever | C22: Nestlé | D22: Wilmar | F22: Basis
A23: Revenue FY2025 (reporting ccy m) | B23: =Fundamentals!I6 -> 50503 | C23: =Fundamentals!I35 -> 89885 | D23: =Fundamentals!I64 -> 70415.7 | F23: Bloomberg FA (EUR / CHF / USD)
A24: COGS FY2025 (reporting ccy m) | B24: =Fundamentals!I7 -> 26794 | C24: =Fundamentals!I36 -> 48694 | D24: =Fundamentals!I65 -> 64619.9 | F24: Bloomberg FA
A25: FX to USD | B25: =$B$11 -> 1.15 | C25: =$B$12 -> 1.25 | D25: 1 | F25: Wilmar reports in USD
A26: Revenue FY2025 (USD m) | B26: =B23*B25 -> 58078.45 | C26: =C23*C25 -> 112356.25 | D26: =D23*D25 -> 70415.7
A27: COGS FY2025 (USD m) | B27: =B24*B25 -> 30813.1 | C27: =C24*C25 -> 60867.5 | D27: =D24*D25 -> 64619.9
A28: a Palm-linked share of revenue | B28: 0.25 | C28: 0.15 | D28: 0.4 | F28: ASSUMPTION — share of sales in products with palm-derived inputs (home/personal care, foods; for Wilmar: palm & laurics, consumer products).
A29: ps Palm-derived spend as % of COGS | B29: 0.03 | C29: 0.015 | D29: 0.3 | F29: ASSUMPTION — calibrate from sustainability reports (tonnes palm × price) divided by COGS.
A30: eu Revenue share in EU-regulated markets | B30: 0.25 | C30: 0.25 | D30: 0.08 | F30: ASSUMPTION — Wilmar low (China 47% of revenue, see Supply_Chain); brand owners via EU retail.
A31: p_reg Annual probability of a regulatory / market-access event | B31: 0.03 | C31: 0.03 | D31: 0.05 | F31: ASSUMPTION — to calibrate from enforcement history; the Wilmar Indonesia probe (May-26) shows the order of magnitude is not zero.
A32: p_ctrv Annual probability of a controversy / boycott event | B32: 0.1 | C32: 0.1 | D32: 0.15 | F32: ASSUMPTION — calibrate from the News_Events frequency (extend to ≥5Y).
A33: rev_loss Revenue lost on palm-linked sales in a controversy | B33: 0.005 | C33: 0.005 | D33: 0.01 | F33: ASSUMPTION — event-study the 2026 Wilmar probe (needs daily prices, see Next_Steps).
A34: Central database: capex (USD m) | B34: 8 | C34: 7 | D34: 25 | F34: ASSUMPTION — planning-grade; replace with vendor quotes / pilot budgets.
A35: Central database: annual opex (USD m) | B35: 3 | C35: 2.5 | D35: 10 | F35: ASSUMPTION
A36: Permissioned blockchain: capex (USD m) | B36: 14 | C36: 12 | D36: 40 | F36: ASSUMPTION — consortium build, node onboarding, integration.
A37: Permissioned blockchain: annual opex (USD m) | B37: 4.5 | C37: 4 | D37: 14 | F37: ASSUMPTION
A39: C. Option design
A40: Parameter | B40: Status quo | C40: Central database | D40: Permissioned blockchain | F40: Basis
A41: cmax Steady-state traceable share | B41: =B10 -> 0.3 | C41: 0.8 | D41: 0.9 | F41: ASSUMPTION — blockchain coverage slightly higher (shared ledger across traders/mills) but slower to coordinate.
A42: Ramp-up years to reach cmax | B42: 1 | C42: 3 | D42: 4
A43: eff Assurance value of coverage (0–1) | B43: 0.6 | C43: 0.8 | D43: 0.9 | F43: ASSUMPTION — KEY: how much extra credibility an immutable multi-party ledger earns with regulators/retailers vs a central database. This single gap decides RQ4.
A45: Mechanics (same in Python): coverage c(t)=c0+(cmax−c0)·min(1,t/ramp); mitigation m=c·eff. Expected annual loss = [p_reg·fine·eu·Revenue + p_ctrv·rev_loss·a·Revenue]·(1−m) + PalmSpend·eu·(1−c)·q·π. Benefit = PV(total cost, status quo) − PV(total cost, option). Year 0 = build (capex only); years 1–7 = operation.

Sheet ROI_ULVR
A1: Unilever — traceability programme: status quo vs central database vs permissioned blockchain (USD m)
A2: Pure calculation sheet: all inputs are green links to 'Assumptions'. Change the scenario on Assumptions!B13. Year 0 = build year.
A4: Revenue, USD m (FY2025) | B4: =Assumptions!B26 -> 58078.45 | D4: Active scenario: | E4: =Assumptions!B13 -> Base
A5: COGS, USD m (FY2025) | B5: =Assumptions!B27 -> 30813.1
A6: a palm-linked revenue share | B6: =Assumptions!B28 -> 0.25
A7: ps palm spend / COGS | B7: =Assumptions!B29 -> 0.03
A8: eu EU-regulated revenue share | B8: =Assumptions!B30 -> 0.25
A9: p_reg (scenario-adjusted) | B9: =Assumptions!B31*Assumptions!$B$19 -> 0.03
A10: p_ctrv (scenario-adjusted) | B10: =Assumptions!B32*Assumptions!$C$19 -> 0.1
A11: rev_loss | B11: =Assumptions!B33 -> 0.005
A12: Realised fine rate | B12: =Assumptions!$B$7 -> 0.02
A13: Substitution premium π (scenario-adjusted) | B13: =Assumptions!$B$8*Assumptions!$D$19 -> 0.06
A14: Share excluded / re-sourced q | B14: =Assumptions!$B$9 -> 0.3
A15: Discount rate | B15: =Assumptions!$B$5 -> 0.08
A16: Growth | B16: =Assumptions!$B$6 -> 0.02
A17: CPO price level × (scenario) | B17: =Assumptions!$E$19 -> 1
A18: Baseline coverage c0 | B18: =Assumptions!$B$10 -> 0.3
A20: Option design | B20: cmax | C20: Ramp (yrs) | D20: eff | E20: Capex | F20: Opex / yr
A21: Status quo | B21: =Assumptions!B41 -> 0.3 | C21: =Assumptions!B42 -> 1 | D21: =Assumptions!B43 -> 0.6 | E21: 0 | F21: 0
A22: Central database | B22: =Assumptions!C41 -> 0.8 | C22: =Assumptions!C42 -> 3 | D22: =Assumptions!C43 -> 0.8 | E22: =Assumptions!B34 -> 8 | F22: =Assumptions!B35 -> 3
A23: Permissioned blockchain | B23: =Assumptions!D41 -> 0.9 | C23: =Assumptions!D42 -> 4 | D23: =Assumptions!D43 -> 0.9 | E23: =Assumptions!B36 -> 14 | F23: =Assumptions!B37 -> 4.5
A26: Year | B26: Year | C26: 0 | D26: 1 | E26: 2 | F26: 3 | G26: 4 | H26: 5 | I26: 6 | J26: 7
A27: Growth factor | C27: =(1+$B$16)^C$26 -> 1 | D27: =(1+$B$16)^D$26 -> 1.02 | E27: =(1+$B$16)^E$26 -> 1.0404 | F27: =(1+$B$16)^F$26 -> 1.061208 | G27: =(1+$B$16)^G$26 -> 1.0824322 | H27: =(1+$B$16)^H$26 -> 1.1040808 | I27: =(1+$B$16)^I$26 -> 1.1261624 | J27: =(1+$B$16)^J$26 -> 1.1486857
A28: Revenue | C28: =$B$4*C27 -> 58078.45 | D28: =$B$4*D27 -> 59240.019 | E28: =$B$4*E27 -> 60424.819 | F28: =$B$4*F27 -> 61633.316 | G28: =$B$4*G27 -> 62865.982 | H28: =$B$4*H27 -> 64123.302 | I28: =$B$4*I27 -> 65405.768 | J28: =$B$4*J27 -> 66713.883
A29: COGS | C29: =$B$5*C27 -> 30813.1 | D29: =$B$5*D27 -> 31429.362 | E29: =$B$5*E27 -> 32057.949 | F29: =$B$5*F27 -> 32699.108 | G29: =$B$5*G27 -> 33353.09 | H29: =$B$5*H27 -> 34020.152 | I29: =$B$5*I27 -> 34700.555 | J29: =$B$5*J27 -> 35394.566
A30: Discount factor | C30: =1/(1+$B$15)^C$26 -> 1 | D30: =1/(1+$B$15)^D$26 -> 0.92592593 | E30: =1/(1+$B$15)^E$26 -> 0.85733882 | F30: =1/(1+$B$15)^F$26 -> 0.79383224 | G30: =1/(1+$B$15)^G$26 -> 0.73502985 | H30: =1/(1+$B$15)^H$26 -> 0.6805832 | I30: =1/(1+$B$15)^I$26 -> 0.63016963 | J30: =1/(1+$B$15)^J$26 -> 0.5834904
A31: CPO price index | C31: =1 -> 1 | D31: =$B$17 -> 1 | E31: =$B$17 -> 1 | F31: =$B$17 -> 1 | G31: =$B$17 -> 1 | H31: =$B$17 -> 1 | I31: =$B$17 -> 1 | J31: =$B$17 -> 1
A32: Palm-derived spend | C32: =C29*$B$7*C31 -> 924.393 | D32: =D29*$B$7*D31 -> 942.88086 | E32: =E29*$B$7*E31 -> 961.73848 | F32: =F29*$B$7*F31 -> 980.97325 | G32: =G29*$B$7*G31 -> 1000.5927 | H32: =H29*$B$7*H31 -> 1020.6046 | I32: =I29*$B$7*I31 -> 1041.0167 | J32: =J29*$B$7*J31 -> 1061.837
A34: Option: Status quo
A35: Traceable coverage | C35: =$B$18 -> 0.3 | D35: =$B$18+($B$21-$B$18)*MIN(1,D$26/$C$21) -> 0.3 | E35: =$B$18+($B$21-$B$18)*MIN(1,E$26/$C$21) -> 0.3 | F35: =$B$18+($B$21-$B$18)*MIN(1,F$26/$C$21) -> 0.3 | G35: =$B$18+($B$21-$B$18)*MIN(1,G$26/$C$21) -> 0.3 | H35: =$B$18+($B$21-$B$18)*MIN(1,H$26/$C$21) -> 0.3 | I35: =$B$18+($B$21-$B$18)*MIN(1,I$26/$C$21) -> 0.3 | J35: =$B$18+($B$21-$B$18)*MIN(1,J$26/$C$21) -> 0.3
A36: Mitigation (coverage × eff) | C36: =C35*$D$21 -> 0.18 | D36: =D35*$D$21 -> 0.18 | E36: =E35*$D$21 -> 0.18 | F36: =F35*$D$21 -> 0.18 | G36: =G35*$D$21 -> 0.18 | H36: =H35*$D$21 -> 0.18 | I36: =I35*$D$21 -> 0.18 | J36: =J35*$D$21 -> 0.18
A37: Regulatory loss (expected) | C37: 0 | D37: =$B$9*$B$12*$B$8*D$28*(1-D36) -> 7.2865223 | E37: =$B$9*$B$12*$B$8*E$28*(1-E36) -> 7.4322528 | F37: =$B$9*$B$12*$B$8*F$28*(1-F36) -> 7.5808978 | G37: =$B$9*$B$12*$B$8*G$28*(1-G36) -> 7.7325158 | H37: =$B$9*$B$12*$B$8*H$28*(1-H36) -> 7.8871661 | I37: =$B$9*$B$12*$B$8*I$28*(1-I36) -> 8.0449094 | J37: =$B$9*$B$12*$B$8*J$28*(1-J36) -> 8.2058076
A38: Supplier substitution cost | C38: 0 | D38: =D$32*$B$8*(1-D35)*$B$14*$B$13 -> 2.9700747 | E38: =E$32*$B$8*(1-E35)*$B$14*$B$13 -> 3.0294762 | F38: =F$32*$B$8*(1-F35)*$B$14*$B$13 -> 3.0900657 | G38: =G$32*$B$8*(1-G35)*$B$14*$B$13 -> 3.151867 | H38: =H$32*$B$8*(1-H35)*$B$14*$B$13 -> 3.2149044 | I38: =I$32*$B$8*(1-I35)*$B$14*$B$13 -> 3.2792025 | J38: =J$32*$B$8*(1-J35)*$B$14*$B$13 -> 3.3447865
A39: Reputational / controversy loss (expected) | C39: 0 | D39: =$B$10*$B$11*$B$6*D$28*(1-D36) -> 6.0721019 | E39: =$B$10*$B$11*$B$6*E$28*(1-E36) -> 6.193544 | F39: =$B$10*$B$11*$B$6*F$28*(1-F36) -> 6.3174149 | G39: =$B$10*$B$11*$B$6*G$28*(1-G36) -> 6.4437632 | H39: =$B$10*$B$11*$B$6*H$28*(1-H36) -> 6.5726384 | I39: =$B$10*$B$11*$B$6*I$28*(1-I36) -> 6.7040912 | J39: =$B$10*$B$11*$B$6*J$28*(1-J36) -> 6.838173
A40: Programme opex | C40: 0 | D40: =$F$21*D$27 -> 0 | E40: =$F$21*E$27 -> 0 | F40: =$F$21*F$27 -> 0 | G40: =$F$21*G$27 -> 0 | H40: =$F$21*H$27 -> 0 | I40: =$F$21*I$27 -> 0 | J40: =$F$21*J$27 -> 0
A41: Programme capex | C41: =$E$21 -> 0 | D41: 0 | E41: 0 | F41: 0 | G41: 0 | H41: 0 | I41: 0 | J41: 0
A42: Total cost (losses + programme) | C42: =SUM(C37:C41) -> 0 | D42: =SUM(D37:D41) -> 16.328699 | E42: =SUM(E37:E41) -> 16.655273 | F42: =SUM(F37:F41) -> 16.988378 | G42: =SUM(G37:G41) -> 17.328146 | H42: =SUM(H37:H41) -> 17.674709 | I42: =SUM(I37:I41) -> 18.028203 | J42: =SUM(J37:J41) -> 18.388767
A43: PV of total cost | C43: =C42*C$30 -> 0 | D43: =D42*D$30 -> 15.119166 | E43: =E42*E$30 -> 14.279212 | F43: =F42*F$30 -> 13.485923 | G43: =G42*G$30 -> 12.736705 | H43: =H42*H$30 -> 12.02911 | I43: =I42*I$30 -> 11.360826 | J43: =J42*J$30 -> 10.729669
A45: Option: Central database
A46: Traceable coverage | C46: =$B$18 -> 0.3 | D46: =$B$18+($B$22-$B$18)*MIN(1,D$26/$C$22) -> 0.46666667 | E46: =$B$18+($B$22-$B$18)*MIN(1,E$26/$C$22) -> 0.63333333 | F46: =$B$18+($B$22-$B$18)*MIN(1,F$26/$C$22) -> 0.8 | G46: =$B$18+($B$22-$B$18)*MIN(1,G$26/$C$22) -> 0.8 | H46: =$B$18+($B$22-$B$18)*MIN(1,H$26/$C$22) -> 0.8 | I46: =$B$18+($B$22-$B$18)*MIN(1,I$26/$C$22) -> 0.8 | J46: =$B$18+($B$22-$B$18)*MIN(1,J$26/$C$22) -> 0.8
...

Sheet ROI_NESN
A1: Nestlé — traceability programme: status quo vs central database vs permissioned blockchain (USD m)
A2: Pure calculation sheet: all inputs are green links to 'Assumptions'. Change the scenario on Assumptions!B13. Year 0 = build year.
A4: Revenue, USD m (FY2025) | B4: =Assumptions!C26 -> 112356.25 | D4: Active scenario: | E4: =Assumptions!B13 -> Base
A5: COGS, USD m (FY2025) | B5: =Assumptions!C27 -> 60867.5
A6: a palm-linked revenue share | B6: =Assumptions!C28 -> 0.15
A7: ps palm spend / COGS | B7: =Assumptions!C29 -> 0.015
A8: eu EU-regulated revenue share | B8: =Assumptions!C30 -> 0.25
A9: p_reg (scenario-adjusted) | B9: =Assumptions!C31*Assumptions!$B$19 -> 0.03
A10: p_ctrv (scenario-adjusted) | B10: =Assumptions!C32*Assumptions!$C$19 -> 0.1
A11: rev_loss | B11: =Assumptions!C33 -> 0.005
A12: Realised fine rate | B12: =Assumptions!$B$7 -> 0.02
A13: Substitution premium π (scenario-adjusted) | B13: =Assumptions!$B$8*Assumptions!$D$19 -> 0.06
A14: Share excluded / re-sourced q | B14: =Assumptions!$B$9 -> 0.3
A15: Discount rate | B15: =Assumptions!$B$5 -> 0.08
A16: Growth | B16: =Assumptions!$B$6 -> 0.02
A17: CPO price level × (scenario) | B17: =Assumptions!$E$19 -> 1
A18: Baseline coverage c0 | B18: =Assumptions!$B$10 -> 0.3
A20: Option design | B20: cmax | C20: Ramp (yrs) | D20: eff | E20: Capex | F20: Opex / yr
A21: Status quo | B21: =Assumptions!B41 -> 0.3 | C21: =Assumptions!B42 -> 1 | D21: =Assumptions!B43 -> 0.6 | E21: 0 | F21: 0
A22: Central database | B22: =Assumptions!C41 -> 0.8 | C22: =Assumptions!C42 -> 3 | D22: =Assumptions!C43 -> 0.8 | E22: =Assumptions!C34 -> 7 | F22: =Assumptions!C35 -> 2.5
A23: Permissioned blockchain | B23: =Assumptions!D41 -> 0.9 | C23: =Assumptions!D42 -> 4 | D23: =Assumptions!D43 -> 0.9 | E23: =Assumptions!C36 -> 12 | F23: =Assumptions!C37 -> 4
A26: Year | B26: Year | C26: 0 | D26: 1 | E26: 2 | F26: 3 | G26: 4 | H26: 5 | I26: 6 | J26: 7
A27: Growth factor | C27: =(1+$B$16)^C$26 -> 1 | D27: =(1+$B$16)^D$26 -> 1.02 | E27: =(1+$B$16)^E$26 -> 1.0404 | F27: =(1+$B$16)^F$26 -> 1.061208 | G27: =(1+$B$16)^G$26 -> 1.0824322 | H27: =(1+$B$16)^H$26 -> 1.1040808 | I27: =(1+$B$16)^I$26 -> 1.1261624 | J27: =(1+$B$16)^J$26 -> 1.1486857
A28: Revenue | C28: =$B$4*C27 -> 112356.25 | D28: =$B$4*D27 -> 114603.38 | E28: =$B$4*E27 -> 116895.44 | F28: =$B$4*F27 -> 119233.35 | G28: =$B$4*G27 -> 121618.02 | H28: =$B$4*H27 -> 124050.38 | I28: =$B$4*I27 -> 126531.39 | J28: =$B$4*J27 -> 129062.01
A29: COGS | C29: =$B$5*C27 -> 60867.5 | D29: =$B$5*D27 -> 62084.85 | E29: =$B$5*E27 -> 63326.547 | F29: =$B$5*F27 -> 64593.078 | G29: =$B$5*G27 -> 65884.939 | H29: =$B$5*H27 -> 67202.638 | I29: =$B$5*I27 -> 68546.691 | J29: =$B$5*J27 -> 69917.625
A30: Discount factor | C30: =1/(1+$B$15)^C$26 -> 1 | D30: =1/(1+$B$15)^D$26 -> 0.92592593 | E30: =1/(1+$B$15)^E$26 -> 0.85733882 | F30: =1/(1+$B$15)^F$26 -> 0.79383224 | G30: =1/(1+$B$15)^G$26 -> 0.73502985 | H30: =1/(1+$B$15)^H$26 -> 0.6805832 | I30: =1/(1+$B$15)^I$26 -> 0.63016963 | J30: =1/(1+$B$15)^J$26 -> 0.5834904
A31: CPO price index | C31: =1 -> 1 | D31: =$B$17 -> 1 | E31: =$B$17 -> 1 | F31: =$B$17 -> 1 | G31: =$B$17 -> 1 | H31: =$B$17 -> 1 | I31: =$B$17 -> 1 | J31: =$B$17 -> 1
A32: Palm-derived spend | C32: =C29*$B$7*C31 -> 913.0125 | D32: =D29*$B$7*D31 -> 931.27275 | E32: =E29*$B$7*E31 -> 949.8982 | F32: =F29*$B$7*F31 -> 968.89617 | G32: =G29*$B$7*G31 -> 988.27409 | H32: =H29*$B$7*H31 -> 1008.0396 | I32: =I29*$B$7*I31 -> 1028.2004 | J32: =J29*$B$7*J31 -> 1048.7644
A34: Option: Status quo
A35: Traceable coverage | C35: =$B$18 -> 0.3 | D35: =$B$18+($B$21-$B$18)*MIN(1,D$26/$C$21) -> 0.3 | E35: =$B$18+($B$21-$B$18)*MIN(1,E$26/$C$21) -> 0.3 | F35: =$B$18+($B$21-$B$18)*MIN(1,F$26/$C$21) -> 0.3 | G35: =$B$18+($B$21-$B$18)*MIN(1,G$26/$C$21) -> 0.3 | H35: =$B$18+($B$21-$B$18)*MIN(1,H$26/$C$21) -> 0.3 | I35: =$B$18+($B$21-$B$18)*MIN(1,I$26/$C$21) -> 0.3 | J35: =$B$18+($B$21-$B$18)*MIN(1,J$26/$C$21) -> 0.3
A36: Mitigation (coverage × eff) | C36: =C35*$D$21 -> 0.18 | D36: =D35*$D$21 -> 0.18 | E36: =E35*$D$21 -> 0.18 | F36: =F35*$D$21 -> 0.18 | G36: =G35*$D$21 -> 0.18 | H36: =H35*$D$21 -> 0.18 | I36: =I35*$D$21 -> 0.18 | J36: =J35*$D$21 -> 0.18
A37: Regulatory loss (expected) | C37: 0 | D37: =$B$9*$B$12*$B$8*D$28*(1-D36) -> 14.096215 | E37: =$B$9*$B$12*$B$8*E$28*(1-E36) -> 14.378139 | F37: =$B$9*$B$12*$B$8*F$28*(1-F36) -> 14.665702 | G37: =$B$9*$B$12*$B$8*G$28*(1-G36) -> 14.959016 | H37: =$B$9*$B$12*$B$8*H$28*(1-H36) -> 15.258197 | I37: =$B$9*$B$12*$B$8*I$28*(1-I36) -> 15.563361 | J37: =$B$9*$B$12*$B$8*J$28*(1-J36) -> 15.874628
A38: Supplier substitution cost | C38: 0 | D38: =D$32*$B$8*(1-D35)*$B$14*$B$13 -> 2.9335092 | E38: =E$32*$B$8*(1-E35)*$B$14*$B$13 -> 2.9921793 | F38: =F$32*$B$8*(1-F35)*$B$14*$B$13 -> 3.0520229 | G38: =G$32*$B$8*(1-G35)*$B$14*$B$13 -> 3.1130634 | H38: =H$32*$B$8*(1-H35)*$B$14*$B$13 -> 3.1753247 | I38: =I$32*$B$8*(1-I35)*$B$14*$B$13 -> 3.2388312 | J38: =J$32*$B$8*(1-J35)*$B$14*$B$13 -> 3.3036078
A39: Reputational / controversy loss (expected) | C39: 0 | D39: =$B$10*$B$11*$B$6*D$28*(1-D36) -> 7.0481076 | E39: =$B$10*$B$11*$B$6*E$28*(1-E36) -> 7.1890697 | F39: =$B$10*$B$11*$B$6*F$28*(1-F36) -> 7.3328511 | G39: =$B$10*$B$11*$B$6*G$28*(1-G36) -> 7.4795081 | H39: =$B$10*$B$11*$B$6*H$28*(1-H36) -> 7.6290983 | I39: =$B$10*$B$11*$B$6*I$28*(1-I36) -> 7.7816803 | J39: =$B$10*$B$11*$B$6*J$28*(1-J36) -> 7.9373139
A40: Programme opex | C40: 0 | D40: =$F$21*D$27 -> 0 | E40: =$F$21*E$27 -> 0 | F40: =$F$21*F$27 -> 0 | G40: =$F$21*G$27 -> 0 | H40: =$F$21*H$27 -> 0 | I40: =$F$21*I$27 -> 0 | J40: =$F$21*J$27 -> 0
A41: Programme capex | C41: =$E$21 -> 0 | D41: 0 | E41: 0 | F41: 0 | G41: 0 | H41: 0 | I41: 0 | J41: 0
A42: Total cost (losses + programme) | C42: =SUM(C37:C41) -> 0 | D42: =SUM(D37:D41) -> 24.077832 | E42: =SUM(E37:E41) -> 24.559388 | F42: =SUM(F37:F41) -> 25.050576 | G42: =SUM(G37:G41) -> 25.551588 | H42: =SUM(H37:H41) -> 26.06262 | I42: =SUM(I37:I41) -> 26.583872 | J42: =SUM(J37:J41) -> 27.115549
A43: PV of total cost | C43: =C42*C$30 -> 0 | D43: =D42*D$30 -> 22.294289 | E43: =E42*E$30 -> 21.055717 | F43: =F42*F$30 -> 19.885955 | G43: =G42*G$30 -> 18.78118 | H43: =H42*H$30 -> 17.737781 | I43: =I42*I$30 -> 16.752349 | J43: =J42*J$30 -> 15.821663
A45: Option: Central database
A46: Traceable coverage | C46: =$B$18 -> 0.3 | D46: =$B$18+($B$22-$B$18)*MIN(1,D$26/$C$22) -> 0.46666667 | E46: =$B$18+($B$22-$B$18)*MIN(1,E$26/$C$22) -> 0.63333333 | F46: =$B$18+($B$22-$B$18)*MIN(1,F$26/$C$22) -> 0.8 | G46: =$B$18+($B$22-$B$18)*MIN(1,G$26/$C$22) -> 0.8 | H46: =$B$18+($B$22-$B$18)*MIN(1,H$26/$C$22) -> 0.8 | I46: =$B$18+($B$22-$B$18)*MIN(1,I$26/$C$22) -> 0.8 | J46: =$B$18+($B$22-$B$18)*MIN(1,J$26/$C$22) -> 0.8
...

Sheet ROI_WIL
A1: Wilmar — traceability programme: status quo vs central database vs permissioned blockchain (USD m)
A2: Pure calculation sheet: all inputs are green links to 'Assumptions'. Change the scenario on Assumptions!B13. Year 0 = build year.
A4: Revenue, USD m (FY2025) | B4: =Assumptions!D26 -> 70415.7 | D4: Active scenario: | E4: =Assumptions!B13 -> Base
A5: COGS, USD m (FY2025) | B5: =Assumptions!D27 -> 64619.9
A6: a palm-linked revenue share | B6: =Assumptions!D28 -> 0.4
A7: ps palm spend / COGS | B7: =Assumptions!D29 -> 0.3
A8: eu EU-regulated revenue share | B8: =Assumptions!D30 -> 0.08
A9: p_reg (scenario-adjusted) | B9: =Assumptions!D31*Assumptions!$B$19 -> 0.05
A10: p_ctrv (scenario-adjusted) | B10: =Assumptions!D32*Assumptions!$C$19 -> 0.15
A11: rev_loss | B11: =Assumptions!D33 -> 0.01
A12: Realised fine rate | B12: =Assumptions!$B$7 -> 0.02
A13: Substitution premium π (scenario-adjusted) | B13: =Assumptions!$B$8*Assumptions!$D$19 -> 0.06
A14: Share excluded / re-sourced q | B14: =Assumptions!$B$9 -> 0.3
A15: Discount rate | B15: =Assumptions!$B$5 -> 0.08
A16: Growth | B16: =Assumptions!$B$6 -> 0.02
A17: CPO price level × (scenario) | B17: =Assumptions!$E$19 -> 1
A18: Baseline coverage c0 | B18: =Assumptions!$B$10 -> 0.3
A20: Option design | B20: cmax | C20: Ramp (yrs) | D20: eff | E20: Capex | F20: Opex / yr
A21: Status quo | B21: =Assumptions!B41 -> 0.3 | C21: =Assumptions!B42 -> 1 | D21: =Assumptions!B43 -> 0.6 | E21: 0 | F21: 0
A22: Central database | B22: =Assumptions!C41 -> 0.8 | C22: =Assumptions!C42 -> 3 | D22: =Assumptions!C43 -> 0.8 | E22: =Assumptions!D34 -> 25 | F22: =Assumptions!D35 -> 10
A23: Permissioned blockchain | B23: =Assumptions!D41 -> 0.9 | C23: =Assumptions!D42 -> 4 | D23: =Assumptions!D43 -> 0.9 | E23: =Assumptions!D36 -> 40 | F23: =Assumptions!D37 -> 14
A26: Year | B26: Year | C26: 0 | D26: 1 | E26: 2 | F26: 3 | G26: 4 | H26: 5 | I26: 6 | J26: 7
A27: Growth factor | C27: =(1+$B$16)^C$26 -> 1 | D27: =(1+$B$16)^D$26 -> 1.02 | E27: =(1+$B$16)^E$26 -> 1.0404 | F27: =(1+$B$16)^F$26 -> 1.061208 | G27: =(1+$B$16)^G$26 -> 1.0824322 | H27: =(1+$B$16)^H$26 -> 1.1040808 | I27: =(1+$B$16)^I$26 -> 1.1261624 | J27: =(1+$B$16)^J$26 -> 1.1486857
A28: Revenue | C28: =$B$4*C27 -> 70415.7 | D28: =$B$4*D27 -> 71824.014 | E28: =$B$4*E27 -> 73260.494 | F28: =$B$4*F27 -> 74725.704 | G28: =$B$4*G27 -> 76220.218 | H28: =$B$4*H27 -> 77744.623 | I28: =$B$4*I27 -> 79299.515 | J28: =$B$4*J27 -> 80885.505
A29: COGS | C29: =$B$5*C27 -> 64619.9 | D29: =$B$5*D27 -> 65912.298 | E29: =$B$5*E27 -> 67230.544 | F29: =$B$5*F27 -> 68575.155 | G29: =$B$5*G27 -> 69946.658 | H29: =$B$5*H27 -> 71345.591 | I29: =$B$5*I27 -> 72772.503 | J29: =$B$5*J27 -> 74227.953
A30: Discount factor | C30: =1/(1+$B$15)^C$26 -> 1 | D30: =1/(1+$B$15)^D$26 -> 0.92592593 | E30: =1/(1+$B$15)^E$26 -> 0.85733882 | F30: =1/(1+$B$15)^F$26 -> 0.79383224 | G30: =1/(1+$B$15)^G$26 -> 0.73502985 | H30: =1/(1+$B$15)^H$26 -> 0.6805832 | I30: =1/(1+$B$15)^I$26 -> 0.63016963 | J30: =1/(1+$B$15)^J$26 -> 0.5834904
A31: CPO price index | C31: =1 -> 1 | D31: =$B$17 -> 1 | E31: =$B$17 -> 1 | F31: =$B$17 -> 1 | G31: =$B$17 -> 1 | H31: =$B$17 -> 1 | I31: =$B$17 -> 1 | J31: =$B$17 -> 1
A32: Palm-derived spend | C32: =C29*$B$7*C31 -> 19385.97 | D32: =D29*$B$7*D31 -> 19773.689 | E32: =E29*$B$7*E31 -> 20169.163 | F32: =F29*$B$7*F31 -> 20572.546 | G32: =G29*$B$7*G31 -> 20983.997 | H32: =H29*$B$7*H31 -> 21403.677 | I32: =I29*$B$7*I31 -> 21831.751 | J32: =J29*$B$7*J31 -> 22268.386
A34: Option: Status quo
A35: Traceable coverage | C35: =$B$18 -> 0.3 | D35: =$B$18+($B$21-$B$18)*MIN(1,D$26/$C$21) -> 0.3 | E35: =$B$18+($B$21-$B$18)*MIN(1,E$26/$C$21) -> 0.3 | F35: =$B$18+($B$21-$B$18)*MIN(1,F$26/$C$21) -> 0.3 | G35: =$B$18+($B$21-$B$18)*MIN(1,G$26/$C$21) -> 0.3 | H35: =$B$18+($B$21-$B$18)*MIN(1,H$26/$C$21) -> 0.3 | I35: =$B$18+($B$21-$B$18)*MIN(1,I$26/$C$21) -> 0.3 | J35: =$B$18+($B$21-$B$18)*MIN(1,J$26/$C$21) -> 0.3
A36: Mitigation (coverage × eff) | C36: =C35*$D$21 -> 0.18 | D36: =D35*$D$21 -> 0.18 | E36: =E35*$D$21 -> 0.18 | F36: =F35*$D$21 -> 0.18 | G36: =G35*$D$21 -> 0.18 | H36: =H35*$D$21 -> 0.18 | I36: =I35*$D$21 -> 0.18 | J36: =J35*$D$21 -> 0.18
A37: Regulatory loss (expected) | C37: 0 | D37: =$B$9*$B$12*$B$8*D$28*(1-D36) -> 4.7116553 | E37: =$B$9*$B$12*$B$8*E$28*(1-E36) -> 4.8058884 | F37: =$B$9*$B$12*$B$8*F$28*(1-F36) -> 4.9020062 | G37: =$B$9*$B$12*$B$8*G$28*(1-G36) -> 5.0000463 | H37: =$B$9*$B$12*$B$8*H$28*(1-H36) -> 5.1000472 | I37: =$B$9*$B$12*$B$8*I$28*(1-I36) -> 5.2020482 | J37: =$B$9*$B$12*$B$8*J$28*(1-J36) -> 5.3060892
A38: Supplier substitution cost | C38: 0 | D38: =D$32*$B$8*(1-D35)*$B$14*$B$13 -> 19.931879 | E38: =E$32*$B$8*(1-E35)*$B$14*$B$13 -> 20.330516 | F38: =F$32*$B$8*(1-F35)*$B$14*$B$13 -> 20.737127 | G38: =G$32*$B$8*(1-G35)*$B$14*$B$13 -> 21.151869 | H38: =H$32*$B$8*(1-H35)*$B$14*$B$13 -> 21.574907 | I38: =I$32*$B$8*(1-I35)*$B$14*$B$13 -> 22.006405 | J38: =J$32*$B$8*(1-J35)*$B$14*$B$13 -> 22.446533
A39: Reputational / controversy loss (expected) | C39: 0 | D39: =$B$10*$B$11*$B$6*D$28*(1-D36) -> 35.337415 | E39: =$B$10*$B$11*$B$6*E$28*(1-E36) -> 36.044163 | F39: =$B$10*$B$11*$B$6*F$28*(1-F36) -> 36.765046 | G39: =$B$10*$B$11*$B$6*G$28*(1-G36) -> 37.500347 | H39: =$B$10*$B$11*$B$6*H$28*(1-H36) -> 38.250354 | I39: =$B$10*$B$11*$B$6*I$28*(1-I36) -> 39.015361 | J39: =$B$10*$B$11*$B$6*J$28*(1-J36) -> 39.795669
A40: Programme opex | C40: 0 | D40: =$F$21*D$27 -> 0 | E40: =$F$21*E$27 -> 0 | F40: =$F$21*F$27 -> 0 | G40: =$F$21*G$27 -> 0 | H40: =$F$21*H$27 -> 0 | I40: =$F$21*I$27 -> 0 | J40: =$F$21*J$27 -> 0
A41: Programme capex | C41: =$E$21 -> 0 | D41: 0 | E41: 0 | F41: 0 | G41: 0 | H41: 0 | I41: 0 | J41: 0
A42: Total cost (losses + programme) | C42: =SUM(C37:C41) -> 0 | D42: =SUM(D37:D41) -> 59.980949 | E42: =SUM(E37:E41) -> 61.180568 | F42: =SUM(F37:F41) -> 62.404179 | G42: =SUM(G37:G41) -> 63.652263 | H42: =SUM(H37:H41) -> 64.925308 | I42: =SUM(I37:I41) -> 66.223814 | J42: =SUM(J37:J41) -> 67.548291
A43: PV of total cost | C43: =C42*C$30 -> 0 | D43: =D42*D$30 -> 55.537916 | E43: =E42*E$30 -> 52.452476 | F43: =F42*F$30 -> 49.53845 | G43: =G42*G$30 -> 46.786314 | H43: =H42*H$30 -> 44.187074 | I43: =I42*I$30 -> 41.732236 | J43: =J42*J$30 -> 39.413779
A45: Option: Central database
A46: Traceable coverage | C46: =$B$18 -> 0.3 | D46: =$B$18+($B$22-$B$18)*MIN(1,D$26/$C$22) -> 0.46666667 | E46: =$B$18+($B$22-$B$18)*MIN(1,E$26/$C$22) -> 0.63333333 | F46: =$B$18+($B$22-$B$18)*MIN(1,F$26/$C$22) -> 0.8 | G46: =$B$18+($B$22-$B$18)*MIN(1,G$26/$C$22) -> 0.8 | H46: =$B$18+($B$22-$B$18)*MIN(1,H$26/$C$22) -> 0.8 | I46: =$B$18+($B$22-$B$18)*MIN(1,I$26/$C$22) -> 0.8 | J46: =$B$18+($B$22-$B$18)*MIN(1,J$26/$C$22) -> 0.8
...

Sheet MC_Results
A1: Monte Carlo results — 20,000 draws per cell, seed 42 (STATIC values from palm_oil_traceability_model.py)
A2: NPV benefit vs status quo, USD m. Same random world is applied to every option (common random numbers). Re-run the script after changing assumptions; these cells do not update by themselves.
A4: Firm | B4: Regime | C4: Option | D4: Mean | E4: 5th pct | F4: Median | G4: 95th pct | H4: P(NPV > 0) | I4: P(blockchain beats database) | J4: Mean (blockchain − database)
A5: Unilever | B5: Base | C5: Central database | D5: 19.372726 | E5: -9.5603664 | F5: 16.348099 | G5: 58.157002 | H5: 0.841
A6: Unilever | B6: Base | C6: Permissioned blockchain | D6: 9.7040342 | E6: -30.156877 | F6: 7.5591098 | G6: 57.453575 | H6: 0.62965 | I6: 0.3198 | J6: -9.6686918
A7: Unilever | B7: Adverse | C7: Central database | D7: 52.375399 | E7: 5.2664951 | F7: 45.141537 | G7: 123.21217 | H7: 0.97385
A8: Unilever | B8: Adverse | C8: Permissioned blockchain | D8: 47.697135 | E8: -9.8415459 | F8: 39.845845 | G8: 132.05336 | H8: 0.90045 | I8: 0.41445 | J8: -4.6782645
A9: Unilever | B9: Severe | C9: Central database | D9: 125.29041 | E9: 36.898822 | F9: 109.9598 | G9: 264.14103 | H9: 0.99905
A10: Unilever | B10: Severe | C10: Permissioned blockchain | D10: 130.58927 | E10: 28.771338 | F10: 112.87718 | G10: 294.04286 | H10: 0.9934 | I10: 0.5195 | J10: 5.2988613
A11: Unilever | B11: Mixed | C11: Central database | D11: 40.85191 | E11: -12.698209 | F11: 17.989507 | G11: 171.75883 | H11: 0.78925
A12: Unilever | B12: Mixed | C12: Permissioned blockchain | D12: 34.141199 | E12: -32.663807 | F12: 9.7294366 | G12: 184.96922 | H12: 0.6236 | I12: 0.35255 | J12: -6.7107113
A13: Nestlé | B13: Base | C13: Central database | D13: 45.168205 | E13: 3.1620487 | F13: 38.042643 | G13: 111.44646 | H13: 0.9684
A14: Nestlé | B14: Base | C14: Permissioned blockchain | D14: 40.549164 | E14: -11.413816 | F14: 32.584989 | G14: 119.09716 | H14: 0.8793 | I14: 0.4016 | J14: -4.6190411
A15: Nestlé | B15: Adverse | C15: Central database | D15: 98.89534 | E15: 22.601235 | F15: 83.32232 | G15: 228.02576 | H15: 0.99735
A16: Nestlé | B16: Adverse | C16: Permissioned blockchain | D16: 102.9453 | E16: 13.433429 | F16: 84.896234 | G16: 255.02897 | H16: 0.98255 | I16: 0.50665 | J16: 4.0499622
A17: Nestlé | B17: Severe | C17: Central database | D17: 213.17421 | E17: 64.121565 | F17: 181.42898 | G17: 468.96869 | H17: 0.99995
A18: Nestlé | B18: Severe | C18: Permissioned blockchain | D18: 234.55849 | E18: 63.602165 | F18: 197.11196 | G18: 533.94533 | H18: 0.99955 | I18: 0.59365 | J18: 21.384286
A19: Nestlé | B19: Mixed | C19: Central database | D19: 79.095657 | E19: -2.1508621 | F19: 39.527506 | G19: 293.53315 | H19: 0.9332
A20: Nestlé | B20: Mixed | C20: Permissioned blockchain | D20: 79.29578 | E20: -16.905702 | F20: 35.635874 | G20: 330.5217 | H20: 0.8275 | I20: 0.42045 | J20: 0.20012276
A21: Wilmar | B21: Base | C21: Central database | D21: 78.11824 | E21: -16.078219 | F21: 70.683213 | G21: 198.13272 | H21: 0.90545
A22: Wilmar | B22: Base | C22: Permissioned blockchain | D22: 53.540337 | E22: -68.233592 | F22: 49.114619 | G22: 190.02262 | H22: 0.7586 | I22: 0.3573 | J22: -24.577903
A23: Wilmar | B23: Adverse | C23: Central database | D23: 165.87761 | E23: 31.72418 | F23: 153.3023 | G23: 344.15472 | H23: 0.98625
A24: Wilmar | B24: Adverse | C24: Permissioned blockchain | D24: 151.11388 | E24: -5.5582086 | F24: 139.43254 | G24: 347.5392 | H24: 0.943 | I24: 0.42325 | J24: -14.763726
A25: Wilmar | B25: Severe | C25: Central database | D25: 387.76644 | E25: 145.63184 | F25: 361.20436 | G25: 721.87105 | H25: 0.99975
A26: Wilmar | B26: Severe | C26: Permissioned blockchain | D26: 392.60604 | E26: 130.07827 | F26: 365.01646 | G26: 748.23575 | H26: 0.99735 | I26: 0.50675 | J26: 4.8396058
A27: Wilmar | B27: Mixed | C27: Central database | D27: 142.56094 | E27: -22.724724 | F27: 81.467556 | G27: 517.52564 | H27: 0.88505
A28: Wilmar | B28: Mixed | C28: Permissioned blockchain | D28: 123.93415 | E28: -69.946226 | F28: 60.441997 | G28: 532.38664 | H28: 0.7567 | I28: 0.38345 | J28: -18.626797
A30: Regimes: Base / Adverse / Severe use the multipliers on Assumptions; 'Mixed' draws a regime per simulation (25% benign EU enforcement, 50% base, 25% severe). Random inputs: event probabilities (log-normal), realised fine 0.5–4%, exclusion share, premium, discount rate 6–11%, baseline coverage, option coverage/ramp/effectiveness (triangular), cost overruns (log-normal), and a CPO price path (GBM, zero drift, σ = 17% estimated from only ~8 weeks of KOZ6 prints — re-estimate on 5Y data).
A33: Distribution of NPV benefit — Unilever, mixed regimes (share of simulations per bin; tails clipped at 1st/99th pct)
A34: Bin mid-point (USD m) | B34: Central database | C34: Permissioned blockchain
A35: -34.9 | B35: 0.00665 | C35: 0.08055
A36: -17.9 | B36: 0.0729 | C36: 0.1663
A37: -0.9 | B37: 0.26285 | C37: 0.22975
A38: 16.1 | B38: 0.23715 | C38: 0.15445
A39: 33.1 | B39: 0.1197 | C39: 0.0902
A40: 50.1 | B40: 0.0637 | C40: 0.0537
A41: 67.2 | B41: 0.0433 | C41: 0.03715
A42: 84.2 | B42: 0.0376 | C42: 0.0309
A43: 101.2 | B43: 0.0295 | C43: 0.02785
A44: 118.2 | B44: 0.0272 | C44: 0.02305
...

Sheet Sensitivity
A1: Sensitivity & simulation grids (STATIC values from the Python model)
A2: One-at-a-time tornado, and the traceability-coverage × supplier-substitution grid required by the project brief.
A4: Unilever, permissioned blockchain — base-case NPV benefit (USD m) | D4: 15.992594
A5: Driver (low case / high case) | B5: Δ NPV, low case | C5: Δ NPV, high case | D5: Swing
A6: Regulatory event probability (x0.5 / x2) | B6: -12.172926 | C6: 24.345852 | D6: =ABS(C6-B6) -> 36.518778
A7: Realised fine rate (1% / 4%) | B7: -12.172926 | C7: 24.345852 | D7: =ABS(C7-B7) -> 36.518778
A8: Programme cost (x1.6 / x0.7) | B8: -23.53566 | C8: 11.76783 | D8: =ABS(C8-B8) -> 35.30349
A9: Controversy probability (x0.5 / x2) | B9: -10.144105 | C9: 20.28821 | D9: =ABS(C9-B9) -> 30.432315
A10: Ramp-up years (7 / 3) | B10: -13.568794 | C10: 4.8704673 | D10: =ABS(C10-B10) -> 18.439261
A11: Substitution premium (3% / 12%) | B11: -5.292316 | C11: 10.584632 | D11: =ABS(C11-B11) -> 15.876948
A12: Steady-state coverage (0.75 / 0.95) | B12: -11.790171 | C12: 3.930057 | D12: =ABS(C12-B12) -> 15.720228
A13: Baseline coverage today (45% / 15%) | B13: -7.7611657 | C13: 7.7611657 | D13: =ABS(C13-B13) -> 15.522331
A14: Blockchain effectiveness (0.75 / 0.97) | B14: -10.125014 | C14: 4.7250064 | D14: =ABS(C14-B14) -> 14.85002
A15: Share excluded / re-sourced (15% / 50%) | B15: -5.292316 | C15: 7.0564213 | D15: =ABS(C15-B15) -> 12.348737
A16: Discount rate (12% / 6%) | B16: -4.8159074 | C16: 2.8608634 | D16: =ABS(C16-B16) -> 7.6767708
A18: Regulatory probability and the realised fine rate enter the model multiplicatively, so they have identical swings — treat them as one 'expected regulatory loss' driver. The result is most sensitive to how likely and how costly enforcement is, and to programme cost and ramp-up speed — not to the blockchain-specific effectiveness number.
A24: Unilever — PV of supplier-substitution cost (USD m) by steady traceable share (rows) and share of non-traceable volume excluded (columns); base substitution premium
A25: Traceable share ↓ / excluded → | B25: 10% | C25: 20% | D25: 30% | E25: 40% | F25: 50%
A26: 20% | B26: 6.2183548 | C26: 12.43671 | D26: 18.655064 | E26: 24.873419 | F26: 31.091774
A27: 30% | B27: 5.4410605 | C27: 10.882121 | D27: 16.323181 | E27: 21.764242 | F27: 27.205302
A28: 40% | B28: 4.6637661 | C28: 9.3275322 | D28: 13.991298 | E28: 18.655064 | F28: 23.318831
A29: 50% | B29: 3.8864718 | C29: 7.7729435 | D29: 11.659415 | E29: 15.545887 | F29: 19.432359
A30: 60% | B30: 3.1091774 | C30: 6.2183548 | D30: 9.3275322 | E30: 12.43671 | F30: 15.545887
A31: 70% | B31: 2.3318831 | C31: 4.6637661 | D31: 6.9956492 | E31: 9.3275322 | F31: 11.659415
A32: 80% | B32: 1.5545887 | C32: 3.1091774 | D32: 4.6637661 | E32: 6.2183548 | F32: 7.7729435
A33: 90% | B33: 0.77729435 | C33: 1.5545887 | D33: 2.3318831 | E33: 3.1091774 | F33: 3.8864718
A34: 100% | B34: 1.7259402e-15 | C34: 3.4518803e-15 | D34: 5.1778205e-15 | E34: 6.9037607e-15 | F34: 8.6297009e-15
A37: Unilever — PV of supplier-substitution cost (USD m) by steady traceable share (rows) and share of non-traceable volume excluded (columns); severe substitution premium (×2.5)
A38: Traceable share ↓ / excluded → | B38: 10% | C38: 20% | D38: 30% | E38: 40% | F38: 50%
A39: 20% | B39: 15.545887 | C39: 31.091774 | D39: 46.637661 | E39: 62.183548 | F39: 77.729435
A40: 30% | B40: 13.602651 | C40: 27.205302 | D40: 40.807954 | E40: 54.410605 | F40: 68.013256
A41: 40% | B41: 11.659415 | C41: 23.318831 | D41: 34.978246 | E41: 46.637661 | F41: 58.297076
A42: 50% | B42: 9.7161794 | C42: 19.432359 | D42: 29.148538 | E42: 38.864718 | F42: 48.580897
A43: 60% | B43: 7.7729435 | C43: 15.545887 | D43: 23.318831 | E43: 31.091774 | F43: 38.864718
A44: 70% | B44: 5.8297076 | C44: 11.659415 | D44: 17.489123 | E44: 23.318831 | F44: 29.148538
A45: 80% | B45: 3.8864718 | C45: 7.7729435 | D45: 11.659415 | E45: 15.545887 | F45: 19.432359
A46: 90% | B46: 1.9432359 | C46: 3.8864718 | D46: 5.8297076 | E46: 7.7729435 | F46: 9.7161794
A47: 100% | B47: 4.3148504e-15 | C47: 8.6297009e-15 | D47: 1.2944551e-14 | E47: 1.7259402e-14 | F47: 2.1574252e-14
A50: Risk heat map: green = cheap to substitute (high coverage or few exclusions), red = costly. Moving traceable share from 30% to 80% removes ~70% of the substitution bill at any exclusion rate — that value comes from traceability itself, whichever technology delivers it.

Sheet Risk_Index
A1: Composite palm-oil traceability risk index (0 = low risk, 100 = high risk) — real indicators
A2: Replaces the draft's synthetic 50-supplier index. Each indicator is scaled 0–100 between a 'no-risk' value (floor) and a 'max-risk' value (cap). Edit blue cells; scores update.
A4: Indicator | B4: Source | C4: No-risk value | D4: Max-risk value | E4: Unilever (raw) | F4: Nestlé (raw) | G4: Wilmar (raw) | H4: Unilever (0–100) | I4: Nestlé (0–100) | J4: Wilmar (0–100) | K4: Weight: Base | L4: Weight: Equal | M4: Weight: Env/Social-heavy
A5: BESG ESG score gap (10 − score, 2024) | B5: ESG | C5: 0 | D5: 10 | E5: =10-ESG!J26 -> 5.18 | F5: =10-ESG!J16 -> 4.72 | G5: =10-ESG!J6 -> 3.85 | H5: =MAX(0,MIN(100,(E5-$C5)/($D5-$C5)*100)) -> 51.8 | I5: =MAX(0,MIN(100,(F5-$C5)/($D5-$C5)*100)) -> 47.2 | J5: =MAX(0,MIN(100,(G5-$C5)/($D5-$C5)*100)) -> 38.5 | K5: 0.15 | L5: 0.1 | M5: 0.15
A6: BESG Social pillar gap (10 − score, 2024) | B6: ESG | C6: 0 | D6: 10 | E6: =10-ESG!J28 -> 7.92 | F6: =10-ESG!J18 -> 5.89 | G6: =10-ESG!J8 -> 3.54 | H6: =MAX(0,MIN(100,(E6-$C6)/($D6-$C6)*100)) -> 79.2 | I6: =MAX(0,MIN(100,(F6-$C6)/($D6-$C6)*100)) -> 58.9 | J6: =MAX(0,MIN(100,(G6-$C6)/($D6-$C6)*100)) -> 35.4 | K6: 0.15 | L6: 0.1 | M6: 0.2
A7: Scope 3 intensity (kt CO2e per USD bn revenue, 2024) | B7: ESG, Fundamentals, FX | C7: 0 | D7: 3000 | E7: =ESG!J32/(Fundamentals!H6*Assumptions!$B$11/1000) -> 1788.8729 | F7: =ESG!J22/(Fundamentals!H35*Assumptions!$B$12/1000) -> 593.10946 | G7: =ESG!J12/(Fundamentals!H64*1/1000) -> 2181.6854 | H7: =MAX(0,MIN(100,(E7-$C7)/($D7-$C7)*100)) -> 59.629097 | I7: =MAX(0,MIN(100,(F7-$C7)/($D7-$C7)*100)) -> 19.770315 | J7: =MAX(0,MIN(100,(G7-$C7)/($D7-$C7)*100)) -> 72.722847 | K7: 0.15 | L7: 0.1 | M7: 0.2
A8: Suppliers with business-conduct risk, % | B8: Supply_Chain (SPLC) | C8: 0 | D8: 0.4 | E8: =Supply_Chain!D18 -> 0.13937282 | F8: =Supply_Chain!C18 -> 0.10629921 | G8: =Supply_Chain!B18 -> 0.36666667 | H8: =MAX(0,MIN(100,(E8-$C8)/($D8-$C8)*100)) -> 34.843206 | I8: =MAX(0,MIN(100,(F8-$C8)/($D8-$C8)*100)) -> 26.574803 | J8: =MAX(0,MIN(100,(G8-$C8)/($D8-$C8)*100)) -> 91.666667 | K8: 0.1 | L8: 0.1 | M8: 0.1
A9: Suppliers with high GHG vs peers, % | B9: Supply_Chain (SPLC) | C9: 0 | D9: 0.25 | E9: =Supply_Chain!D19 -> 0.20557491 | F9: =Supply_Chain!C19 -> 0.19488189 | G9: =Supply_Chain!B19 -> 0.13333333 | H9: =MAX(0,MIN(100,(E9-$C9)/($D9-$C9)*100)) -> 82.229965 | I9: =MAX(0,MIN(100,(F9-$C9)/($D9-$C9)*100)) -> 77.952756 | J9: =MAX(0,MIN(100,(G9-$C9)/($D9-$C9)*100)) -> 53.333333 | K9: 0.05 | L9: 0.1 | M9: 0.1
A10: Suppliers that are ESG-score laggards, % | B10: Supply_Chain (SPLC) | C10: 0 | D10: 0.1 | E10: =Supply_Chain!D20 -> 0.045296167 | F10: =Supply_Chain!C20 -> 0.041338583 | G10: =Supply_Chain!B20 -> 0.033333333 | H10: =MAX(0,MIN(100,(E10-$C10)/($D10-$C10)*100)) -> 45.296167 | I10: =MAX(0,MIN(100,(F10-$C10)/($D10-$C10)*100)) -> 41.338583 | J10: =MAX(0,MIN(100,(G10-$C10)/($D10-$C10)*100)) -> 33.333333 | K10: 0.05 | L10: 0.1 | M10: 0.05
A11: Sanctioned + distressed suppliers, % | B11: Supply_Chain (SPLC) | C11: 0 | D11: 0.05 | E11: =Supply_Chain!D17 -> 0.017421603 | F11: =Supply_Chain!C17 -> 0.029527559 | G11: =Supply_Chain!B17 -> 0.033333333 | H11: =MAX(0,MIN(100,(E11-$C11)/($D11-$C11)*100)) -> 34.843206 | I11: =MAX(0,MIN(100,(F11-$C11)/($D11-$C11)*100)) -> 59.055118 | J11: =MAX(0,MIN(100,(G11-$C11)/($D11-$C11)*100)) -> 66.666667 | K11: 0.1 | L11: 0.1 | M11: 0.05
A12: Adverse news severity, 12M (see warning on News_Events) | B12: News_Events | C12: 0 | D12: 20 | E12: =News_Events!C7 -> 12 | F12: =News_Events!C8 -> 1 | G12: =News_Events!C9 -> 19 | H12: =MAX(0,MIN(100,(E12-$C12)/($D12-$C12)*100)) -> 60 | I12: =MAX(0,MIN(100,(F12-$C12)/($D12-$C12)*100)) -> 5 | J12: =MAX(0,MIN(100,(G12-$C12)/($D12-$C12)*100)) -> 95 | K12: 0.1 | L12: 0.1 | M12: 0.05
A13: Equity volatility, 90-day (% ann.) | B13: Market_Data | C13: 10 | D13: 40 | E13: =Market_Data!D26 -> 23.1949 | F13: =Market_Data!C26 -> 23.9151 | G13: =Market_Data!B26 -> 21.6096 | H13: =MAX(0,MIN(100,(E13-$C13)/($D13-$C13)*100)) -> 43.983 | I13: =MAX(0,MIN(100,(F13-$C13)/($D13-$C13)*100)) -> 46.383667 | J13: =MAX(0,MIN(100,(G13-$C13)/($D13-$C13)*100)) -> 38.698667 | K13: 0.05 | L13: 0.1 | M13: 0
A14: Interest cover, 2025 (OI / interest) — lower = riskier | B14: Fundamentals | C14: 12 | D14: 2 | E14: =Fundamentals!I26 -> 9.134058 | F14: =Fundamentals!I55 -> 8.2869875 | G14: =Fundamentals!I84 -> 2.0826063 | H14: =MAX(0,MIN(100,(E14-$C14)/($D14-$C14)*100)) -> 28.65942 | I14: =MAX(0,MIN(100,(F14-$C14)/($D14-$C14)*100)) -> 37.130125 | J14: =MAX(0,MIN(100,(G14-$C14)/($D14-$C14)*100)) -> 99.173937 | K14: 0.1 | L14: 0.1 | M14: 0.1
A15: Weight check (must be 100%) | K15: =SUM(K5:K14) -> 1 | L15: =SUM(L5:L14) -> 1 | M15: =SUM(M5:M14) -> 1
A17: Composite score | H17: Unilever | I17: Nestlé | J17: Wilmar
A18: Base weights | H18: =SUMPRODUCT(H$5:H$14,$K$5:$K$14) -> 53.004404 | I18: =SUMPRODUCT(I$5:I$14,$K$5:$K$14) -> 39.940302 | J18: =SUMPRODUCT(J$5:J$14,$K$5:$K$14) -> 63.512421
A19: Equal weights | H19: =SUMPRODUCT(H$5:H$14,$L$5:$L$14) -> 52.048406 | I19: =SUMPRODUCT(I$5:I$14,$L$5:$L$14) -> 41.930537 | J19: =SUMPRODUCT(J$5:J$14,$L$5:$L$14) -> 62.449545
A20: Env/Social-heavy | H20: =SUMPRODUCT(H$5:H$14,$M$5:$M$14) -> 57.116047 | I20: =SUMPRODUCT(I$5:I$14,$M$5:$M$14) -> 42.249517 | J20: =SUMPRODUCT(J$5:J$14,$M$5:$M$14) -> 61.566963
A21: Rank (1 = highest risk) — Base weights | H21: =RANK(H18,$H18:$J18,0) -> 2 | I21: =RANK(I18,$H18:$J18,0) -> 3 | J21: =RANK(J18,$H18:$J18,0) -> 1
A22: Rank (1 = highest risk) — Equal weights | H22: =RANK(H19,$H19:$J19,0) -> 2 | I22: =RANK(I19,$H19:$J19,0) -> 3 | J22: =RANK(J19,$H19:$J19,0) -> 1
A23: Rank (1 = highest risk) — Env/Social-heavy | H23: =RANK(H20,$H20:$J20,0) -> 2 | I23: =RANK(I20,$H20:$J20,0) -> 3 | J23: =RANK(J20,$H20:$J20,0) -> 1
A24: Ranking stable across the three weight sets? | H24: =IF(AND(H21=H22,H21=H23,I21=I22,I21=I23,J21=J22,J21=J23),"Yes","No — weights matter") -> Yes
A26: How to read: with only three firms the index is a RELATIVE ranking and a worked example of the method — not a validated risk model. To make it publishable: (1) extend to 10–15 firms (add IOI, Musim Mas, AAK, Cargill, P&G, Mondelez, Colgate); (2) score Wilmar's 30 suppliers at node level; (3) calibrate weights against an outcome (e.g. forward 3-month drawdown or controversy count after each event) instead of choosing them by judgement. Unilever's Social-pillar gap dominates its score; Wilmar's is driven by interest cover, supplier conduct risk and news severity.

Sheet Supply_Chain
A1: Supply chain — Bloomberg SPLC (as of 15-Oct-2026)
A2: Blue = typed from SPLC screens. Only the rows visible on screen were captured, so every 'coverage' figure is a LOWER bound on what SPLC holds.
A4: A. SPLC summary panels
A5: Metric | B5: Wilmar | C5: Nestlé | D5: Unilever
A6: Suppliers listed (count) | B6: 30 | C6: 508 | D6: 287
A7: Customers listed (count) | B7: 17 | C7: 172 | D7: 126
A8: Suppliers with sanctions | B8: 1 | C8: 2 | D8: 1
A9: Customers with sanctions | B9: 0 | C9: 3 | D9: 1
A10: Suppliers distressed | B10: 0 | C10: 13 | D10: 4
A11: Customers distressed | B11: 1 | C11: 4 | D11: 3
A12: Suppliers = ESG-score laggards (count) | B12: 1 | C12: 21 | D12: 13
A13: Suppliers = business-conduct risk (count) | B13: 11 | C13: 54 | D13: 40
A14: Suppliers = high GHG vs peers (count) | B14: 4 | C14: 99 | D14: 59
A15: Suppliers = high physical risk (count) | B15: 2 | C15: 11 | D15: 6
A16: Suppliers = high water stress (count) | B16: 5 | C16: 71 | D16: 72
A17: Sanctioned + distressed suppliers, % of suppliers | B17: =(B8+B10)/B6 -> 0.033333333 | C17: =(C8+C10)/C6 -> 0.029527559 | D17: =(D8+D10)/D6 -> 0.017421603
A18: Business-conduct-risk suppliers, % | B18: =B13/B6 -> 0.36666667 | C18: =C13/C6 -> 0.10629921 | D18: =D13/D6 -> 0.13937282
A19: High-GHG suppliers, % | B19: =B14/B6 -> 0.13333333 | C19: =C14/C6 -> 0.19488189 | D19: =D14/D6 -> 0.20557491
A20: ESG-laggard suppliers, % | B20: =B12/B6 -> 0.033333333 | C20: =C12/C6 -> 0.041338583 | D20: =D12/D6 -> 0.045296167
A21: High-water-stress suppliers, % | B21: =B16/B6 -> 0.16666667 | C21: =C16/C6 -> 0.13976378 | D21: =D16/D6 -> 0.25087108
A23: B. Geography (revenue / own facilities / supplier facilities, % of total)
A24: Wilmar | B24: Revenue % | C24: Facilities % | D24: Supplier facilities %
A25: China | B25: 0.4733 | C25: 0.2825 | D25: 0.1761
A26: Indonesia | B26: 0.0444 | C26: 0.2177 | D26: 0.0344
A27: Malaysia | B27: 0.0353 | C27: 0.1089 | D27: 0.08
A28: Australia | B28: 0.0327 | C28: 0.0968 | D28: 0.0172
A29: India | B29: 0.0389 | C29: 0.0685 | D29: 0.0273
A31: Nestlé | B31: Revenue % | C31: Facilities % | D31: Supplier facilities %
A32: USA | B32: 0.3392 | C32: 0.2549 | D32: 0.3249
A33: Brazil | B33: 0.0226 | C33: 0.0562 | D33: 0.0271
A34: France | C34: 0.0475 | D34: 0.0396
A35: Chile | C35: 0.0367 | D35: 0.0096
A36: United Kingdom | C36: 0.0367 | D36: 0.0452
A38: Unilever | B38: Revenue % | C38: Facilities % | D38: Supplier facilities %
A39: India | B39: 0.0433 | C39: 0.2283 | D39: 0.0491
A40: USA | B40: 0.2055 | C40: 0.0868 | D40: 0.3157
A41: United Kingdom | B41: 0.1474 | C41: 0.0502 | D41: 0.0451
A42: Brazil | B42: 0.0747 | C42: 0.0457 | D42: 0.0246
A43: China | B43: 0.1967 | C43: 0.0365 | D43: 0.0907
A45: Read-across: 47% of Wilmar's revenue is China; EU exposure is indirect (via customers). EUDR pressure reaches Wilmar through Unilever/Nestlé-type buyers, not through Wilmar's own EU sales — the ROI sheets use a low EU share for Wilmar for this reason.
...

Sheet News_Events
A1: News & controversy log — hand-coded from Bloomberg CN screens
A2: One row per event cluster (many headlines on the same event count once). Antitrust events are logged but excluded from the adverse score (not supply-chain related). Category, sentiment and severity are MY judgement from headlines — re-code with your own rubric.
A4: As-of date | B4: 46310 | C4: 12M window start | D4: =EDATE(B4,-12) -> 45945
A6: Company | B6: Adverse events (12M, excl. antitrust) | C6: Severity-weighted (12M) | D6: Positive/mitigation events (12M) | E6: Headlines in log (12M) | F6: Screen filter used
A7: ULVR | B7: =COUNTIFS($B$14:$B$35,A7,$H$14:$H$35,TRUE(),$E$14:$E$35,-1,$D$14:$D$35,"<>Antitrust*") -> 5 | C7: =SUMIFS($I$14:$I$35,$B$14:$B$35,A7) -> 12 | D7: =COUNTIFS($B$14:$B$35,A7,$H$14:$H$35,TRUE(),$E$14:$E$35,1) -> 0 | E7: =SUMIFS($G$14:$G$35,$B$14:$B$35,A7,$H$14:$H$35,TRUE()) -> 12 | F7: ESG (+ Palm Oil/deforestation, older)
A8: NESN | B8: =COUNTIFS($B$14:$B$35,A8,$H$14:$H$35,TRUE(),$E$14:$E$35,-1,$D$14:$D$35,"<>Antitrust*") -> 1 | C8: =SUMIFS($I$14:$I$35,$B$14:$B$35,A8) -> 1 | D8: =COUNTIFS($B$14:$B$35,A8,$H$14:$H$35,TRUE(),$E$14:$E$35,1) -> 0 | E8: =SUMIFS($G$14:$G$35,$B$14:$B$35,A8,$H$14:$H$35,TRUE()) -> 5 | F8: Palm Oil ONLY
A9: WIL | B9: =COUNTIFS($B$14:$B$35,A9,$H$14:$H$35,TRUE(),$E$14:$E$35,-1,$D$14:$D$35,"<>Antitrust*") -> 6 | C9: =SUMIFS($I$14:$I$35,$B$14:$B$35,A9) -> 19 | D9: =COUNTIFS($B$14:$B$35,A9,$H$14:$H$35,TRUE(),$E$14:$E$35,1) -> 2 | E9: =SUMIFS($G$14:$G$35,$B$14:$B$35,A9,$H$14:$H$35,TRUE()) -> 26 | F9: ESG + Palm Oil
A11: WARNING — not like-for-like: the three companies were screened with different search filters (Nestlé: 'Palm Oil' only, which returns mostly sell-side cost notes). Re-run all three with the SAME query, e.g. company AND (palm oil OR deforestation OR 'supply chain') with ESG/controversy tags, before relying on the news score. Weight kept low in the index for this reason.
A13: Date | B13: Co. | C13: Event cluster | D13: Category | E13: Sentiment (-1/0/+1) | F13: Severity 0–5 | G13: # headlines | H13: In 12M window? | I13: Adverse severity counted | J13: Screen filter
A14: 46308 | B14: WIL | C14: Wilmar tops global children's-rights benchmark for 5th consecutive year | D14: ESG – positive | E14: 1 | F14: 0 | G14: 1 | H14: =AND(A14>=$D$4,A14<=$B$4) -> TRUE | I14: =IF(AND(H14,E14<0,LEFT(D14,9)<>"Antitrust"),F14,0) -> 0 | J14: Wilmar + Palm Oil
A15: 46276 | B15: WIL | C15: Pakistan regulator probe vs Unity on Wilmar's complaint (Wilmar is complainant) | D15: Regulatory – non-adverse | E15: 0 | F15: 0 | G15: 3 | H15: =AND(A15>=$D$4,A15<=$B$4) -> TRUE | I15: =IF(AND(H15,E15<0,LEFT(D15,9)<>"Antitrust"),F15,0) -> 0 | J15: Wilmar + Palm Oil
A16: 46272 | B16: WIL | C16: ABF–Wilmar JV control of Hebei Mauri cleared in EU | D16: M&A – positive | E16: 1 | F16: 0 | G16: 1 | H16: =AND(A16>=$D$4,A16<=$B$4) -> TRUE | I16: =IF(AND(H16,E16<0,LEFT(D16,9)<>"Antitrust"),F16,0) -> 0 | J16: Wilmar + Palm Oil
A17: 46289 | B17: WIL | C17: Palm-oil prices capped for now; war risk, El Niño 2027 gains (BI) | D17: Commodity / price | E17: 0 | F17: 0 | G17: 3 | H17: =AND(A17>=$D$4,A17<=$B$4) -> TRUE | I17: =IF(AND(H17,E17<0,LEFT(D17,9)<>"Antitrust"),F17,0) -> 0 | J17: Wilmar + Palm Oil
A18: 46246 | B18: WIL | C18: Shares fall most in two months on earnings miss; 1H net income $608.9M vs $594.9M | D18: Earnings | E18: -1 | F18: 1 | G18: 3 | H18: =AND(A18>=$D$4,A18<=$B$4) -> TRUE | I18: =IF(AND(H18,E18<0,LEFT(D18,9)<>"Antitrust"),F18,0) -> 1 | J18: Wilmar + Palm Oil
A19: 46170 | B19: WIL | C19: Indonesia export under-invoicing / transfer-pricing probe of palm firms; Wilmar shares fall most in six years | D19: Regulatory / legal | E19: -1 | F19: 5 | G19: 10 | H19: =AND(A19>=$D$4,A19<=$B$4) -> TRUE | I19: =IF(AND(H19,E19<0,LEFT(D19,9)<>"Antitrust"),F19,0) -> 5 | J19: Wilmar + ESG
A20: 46150 | B20: WIL | C20: Russian government to seize Wilmar stake in indirect unit amid corruption allegations | D20: Legal / geopolitical | E20: -1 | F20: 4 | G20: 1 | H20: =AND(A20>=$D$4,A20<=$B$4) -> TRUE | I20: =IF(AND(H20,E20<0,LEFT(D20,9)<>"Antitrust"),F20,0) -> 4 | J20: Wilmar + ESG
A21: 46120 | B21: WIL | C21: Glass Lewis controversy alert on Wilmar | D21: Governance | E21: -1 | F21: 2 | G21: 1 | H21: =AND(A21>=$D$4,A21<=$B$4) -> TRUE | I21: =IF(AND(H21,E21<0,LEFT(D21,9)<>"Antitrust"),F21,0) -> 2 | J21: Wilmar + ESG
